-- Error: tests/neg-custom-args/captures/exception-definitions.scala:2:6 -----------------------------------------------
2 |class Err extends Exception: // error
  |^
  |reference (scala.caps.* : Any) is not included in allowed capture set {} of an exception class
3 |  self: {*} Err =>
-- Error: tests/neg-custom-args/captures/exception-definitions.scala:7:12 ----------------------------------------------
7 |    val x = c  // error
  |            ^
  |   (c : {*} Any) cannot be referenced here; it is not included in the allowed capture set {} of an exception class
-- Error: tests/neg-custom-args/captures/exception-definitions.scala:8:8 -----------------------------------------------
8 |  class Err3(c: {*} Any) extends Exception // error
  |  ^^^^^^^^^^^^^^^^^^^^^^^^^^^^^^^^^^^^^^^^
  |  reference (Err3.this.c : {*} Any) is not included in allowed capture set {} of an exception class
